<?xml version="1.0" encoding="utf-8"?>
<!-- =================================================================================== -->
<!-- |    This document was autogenerated by xacro from dream_walker.urdf.xacro        | -->
<!-- |    EDITING THIS FILE BY HAND IS NOT RECOMMENDED                                 | -->
<!-- =================================================================================== -->
<robot name="dream_walker">
  <material name="red">
    <color rgba="1.0 0.0 0.0 2.0"/>
  </material>
  <material name="gray">
    <color rgba="0.4 0.4 0.6 2.0"/>
  </material>
  <material name="light_gray">
    <color rgba="0.8 0.8 0.8 2.0"/>
  </material>
  <material name="silver">
    <color rgba="0.75 0.75 0.75 2.0"/>
  </material>
  <material name="black">
    <color rgba="0.3 0.3 0.3 2.0"/>
  </material>
  <!-- body -->
  <link name="base_link"/>
  <joint name="body_link_joint" type="fixed">
    <parent link="base_link"/>
    <child link="body_link"/>
  </joint>
  <link name="body_link">
    <visual>
      <geometry>
        <mesh filename="package://dream_walker_description/meshes/body.STL"/>
      </geometry>
      <material name="">
        <color rgba="0.8 0.8 0.8 2.0"/>
      </material>
    </visual>
    <collision>
      <geometry>
        <mesh filename="package://dream_walker_description/meshes/body.STL"/>
      </geometry>
    </collision>
    <inertial>
      <origin xyz="0 0 0"/>
      <mass value="3.0"/>
      <inertia ixx="0.027819" ixy="1.0E-6" ixz="0" iyy="0.106496" iyz="0" izz="0.113695"/>
    </inertial>
  </link>
  <joint name="A0_joint" type="fixed">
    <origin rpy="0 0 0" xyz="0.3 -0.083 0.0"/>
    <parent link="base_link"/>
    <child link="A0_link"/>
    <axis xyz="0 0 0"/>
  </joint>
  <link name="A0_link">
    <visual>
      <origin xyz="-0.3 0.083 -0.0"/>
      <geometry>
        <mesh filename="package://dream_walker_description/meshes/A0_link.STL"/>
      </geometry>
      <material name="black"/>
    </visual>
    <collision>
      <origin xyz="-0.3 0.083 -0.0"/>
      <geometry>
        <mesh filename="package://dream_walker_description/meshes/A0_link.STL"/>
      </geometry>
    </collision>
    <inertial>
      <origin xyz="-0.039 2e-05 -1e-05"/>
      <mass value="1.75"/>
      <inertia ixx="0.002137" ixy="-1e-06" ixz="5e-06" iyy="0.002443" iyz="0" izz="0.002444"/>
    </inertial>
  </link>
  <joint name="B0_joint" type="fixed">
    <origin rpy="0 0 0" xyz="0.3 0.083 0.0"/>
    <parent link="base_link"/>
    <child link="B0_link"/>
    <axis xyz="0 0 0"/>
  </joint>
  <link name="B0_link">
    <visual>
      <origin xyz="-0.3 -0.083 -0.0"/>
      <geometry>
        <mesh filename="package://dream_walker_description/meshes/B0_link.STL"/>
      </geometry>
      <material name="black"/>
    </visual>
    <collision>
      <origin xyz="-0.3 -0.083 -0.0"/>
      <geometry>
        <mesh filename="package://dream_walker_description/meshes/B0_link.STL"/>
      </geometry>
    </collision>
    <inertial>
      <origin xyz="-0.039 -2e-05 -1e-05"/>
      <mass value="1.75"/>
      <inertia ixx="0.002137" ixy="1e-06" ixz="5e-06" iyy="0.002443" iyz="0" izz="0.002444"/>
    </inertial>
  </link>
  <joint name="C0_joint" type="fixed">
    <origin rpy="0 0 0" xyz="-0.3 -0.083 0.0"/>
    <parent link="base_link"/>
    <child link="C0_link"/>
    <axis xyz="0 0 0"/>
  </joint>
  <link name="C0_link">
    <visual>
      <origin xyz="0.3 0.083 -0.0"/>
      <geometry>
        <mesh filename="package://dream_walker_description/meshes/C0_link.STL"/>
      </geometry>
      <material name="black"/>
    </visual>
    <collision>
      <origin xyz="0.3 0.083 -0.0"/>
      <geometry>
        <mesh filename="package://dream_walker_description/meshes/C0_link.STL"/>
      </geometry>
    </collision>
    <inertial>
      <origin xyz="0.039 2e-05 -1e-05"/>
      <mass value="1.75"/>
      <inertia ixx="0.002137" ixy="-1e-06" ixz="5e-06" iyy="0.002443" iyz="0" izz="0.002444"/>
    </inertial>
  </link>
  <joint name="D0_joint" type="fixed">
    <origin rpy="0 0 0" xyz="-0.3 0.083 0.0"/>
    <parent link="base_link"/>
    <child link="D0_link"/>
    <axis xyz="0 0 0"/>
  </joint>
  <link name="D0_link">
    <visual>
      <origin xyz="0.3 -0.083 -0.0"/>
      <geometry>
        <mesh filename="package://dream_walker_description/meshes/D0_link.STL"/>
      </geometry>
      <material name="black"/>
    </visual>
    <collision>
      <origin xyz="0.3 -0.083 -0.0"/>
      <geometry>
        <mesh filename="package://dream_walker_description/meshes/D0_link.STL"/>
      </geometry>
    </collision>
    <inertial>
      <origin xyz="0.039 -2e-05 -1e-05"/>
      <mass value="1.75"/>
      <inertia ixx="0.002137" ixy="-1e-06" ixz="5e-06" iyy="0.002443" iyz="0" izz="0.002444"/>
    </inertial>
  </link>
  <joint name="A1_joint" type="revolute">
    <origin rpy="0 0 0" xyz="0.0835 -0.0 0.0"/>
    <parent link="A0_link"/>
    <child link="A1_link"/>
    <axis xyz="1 0 0"/>
    <limit effort="1000" lower="-3.1416" upper="3.1416" velocity="1000"/>
  </joint>
  <link name="A1_link">
    <visual>
      <origin xyz="-0.3835 0.083 -0.0"/>
      <geometry>
        <mesh filename="package://dream_walker_description/meshes/A1_link.STL"/>
      </geometry>
      <material name="black"/>
    </visual>
    <collision>
      <origin xyz="-0.3835 0.083 -0.0"/>
      <geometry>
        <mesh filename="package://dream_walker_description/meshes/A1_link.STL"/>
      </geometry>
    </collision>
    <inertial>
      <origin xyz="-0.0044 0.00113 -5e-05"/>
      <mass value="1.74"/>
      <inertia ixx="0.00229" ixy="8e-06" ixz="1e-06" iyy="0.002657" iyz="1e-06" izz="0.002511"/>
    </inertial>
  </link>
  <joint name="B1_joint" type="revolute">
    <origin rpy="0 0 0" xyz="0.0835 0.0 0.0"/>
    <parent link="B0_link"/>
    <child link="B1_link"/>
    <axis xyz="1 0 0"/>
    <limit effort="1000" lower="-3.1416" upper="3.1416" velocity="1000"/>
  </joint>
  <link name="B1_link">
    <visual>
      <origin xyz="-0.3835 -0.083 -0.0"/>
      <geometry>
        <mesh filename="package://dream_walker_description/meshes/B1_link.STL"/>
      </geometry>
      <material name="black"/>
    </visual>
    <collision>
      <origin xyz="-0.3835 -0.083 -0.0"/>
      <geometry>
        <mesh filename="package://dream_walker_description/meshes/B1_link.STL"/>
      </geometry>
    </collision>
    <inertial>
      <origin xyz="-0.0044 -0.00113 -5e-05"/>
      <mass value="1.74"/>
      <inertia ixx="0.00229" ixy="8e-06" ixz="1e-06" iyy="0.002657" iyz="1e-06" izz="0.002511"/>
    </inertial>
  </link>
  <joint name="C1_joint" type="revolute">
    <origin rpy="0 0 0" xyz="-0.0835 -0.0 0.0"/>
    <parent link="C0_link"/>
    <child link="C1_link"/>
    <axis xyz="1 0 0"/>
    <limit effort="1000" lower="-3.1416" upper="3.1416" velocity="1000"/>
  </joint>
  <link name="C1_link">
    <visual>
      <origin xyz="0.3835 0.083 -0.0"/>
      <geometry>
        <mesh filename="package://dream_walker_description/meshes/C1_link.STL"/>
      </geometry>
      <material name="black"/>
    </visual>
    <collision>
      <origin xyz="0.3835 0.083 -0.0"/>
      <geometry>
        <mesh filename="package://dream_walker_description/meshes/C1_link.STL"/>
      </geometry>
    </collision>
    <inertial>
      <origin xyz="0.0044 0.00113 -5e-05"/>
      <mass value="1.74"/>
      <inertia ixx="0.00229" ixy="-8e-06" ixz="1e-06" iyy="0.002657" iyz="1e-06" izz="0.002511"/>
    </inertial>
  </link>
  <joint name="D1_joint" type="revolute">
    <origin rpy="0 0 0" xyz="-0.0835 0.0 0.0"/>
    <parent link="D0_link"/>
    <child link="D1_link"/>
    <axis xyz="1 0 0"/>
    <limit effort="1000" lower="-3.1416" upper="3.1416" velocity="1000"/>
  </joint>
  <link name="D1_link">
    <visual>
      <origin xyz="0.3835 -0.083 -0.0"/>
      <geometry>
        <mesh filename="package://dream_walker_description/meshes/D1_link.STL"/>
      </geometry>
      <material name="black"/>
    </visual>
    <collision>
      <origin xyz="0.3835 -0.083 -0.0"/>
      <geometry>
        <mesh filename="package://dream_walker_description/meshes/D1_link.STL"/>
      </geometry>
    </collision>
    <inertial>
      <origin xyz="0.0044 -0.00113 -5e-05"/>
      <mass value="1.74"/>
      <inertia ixx="0.00229" ixy="-8e-06" ixz="1e-06" iyy="0.002657" iyz="1e-06" izz="0.002511"/>
    </inertial>
  </link>
  <joint name="A2_joint" type="revolute">
    <origin rpy="0 0 0" xyz="0.0 -0.2095 0.0"/>
    <parent link="A1_link"/>
    <child link="A2_link"/>
    <axis xyz="0 1 0"/>
    <limit effort="1000" lower="-9.42" upper="9.42" velocity="1000"/>
  </joint>
  <link name="A2_link">
    <visual>
      <origin xyz="-0.3835 0.2925 0.0"/>
      <geometry>
        <mesh filename="package://dream_walker_description/meshes/A2_link.STL"/>
      </geometry>
      <material name="red"/>
    </visual>
    <collision>
      <origin xyz="-0.3835 0.2925 0.0"/>
      <geometry>
        <mesh filename="package://dream_walker_description/meshes/A2_link.STL"/>
      </geometry>
    </collision>
    <inertial>
      <origin xyz="0.0 0.04882 -0.09719"/>
      <mass value="3.66"/>
      <inertia ixx="0.075241" ixy="0" ixz="-5e-06" iyy="0.069683" iyz="0.013776" izz="0.011896"/>
    </inertial>
  </link>
  <joint name="B2_joint" type="revolute">
    <origin rpy="0 0 0" xyz="0.0 0.2095 0.0"/>
    <parent link="B1_link"/>
    <child link="B2_link"/>
    <axis xyz="0 1 0"/>
    <limit effort="1000" lower="-9.42" upper="9.42" velocity="1000"/>
  </joint>
  <link name="B2_link">
    <visual>
      <origin xyz="-0.3835 -0.2925 0.0"/>
      <geometry>
        <mesh filename="package://dream_walker_description/meshes/B2_link.STL"/>
      </geometry>
      <material name="red"/>
    </visual>
    <collision>
      <origin xyz="-0.3835 -0.2925 0.0"/>
      <geometry>
        <mesh filename="package://dream_walker_description/meshes/B2_link.STL"/>
      </geometry>
    </collision>
    <inertial>
      <origin xyz="-0.0 -0.04882 -0.09719"/>
      <mass value="3.66"/>
      <inertia ixx="0.075241" ixy="0" ixz="5e-06" iyy="0.069683" iyz="-0.013776" izz="0.011896"/>
    </inertial>
  </link>
  <joint name="C2_joint" type="revolute">
    <origin rpy="0 0 0" xyz="-0.0 -0.2095 0.0"/>
    <parent link="C1_link"/>
    <child link="C2_link"/>
    <axis xyz="0 1 0"/>
    <limit effort="1000" lower="-9.42" upper="9.42" velocity="1000"/>
  </joint>
  <link name="C2_link">
    <visual>
      <origin xyz="0.3835 0.2925 0.0"/>
      <geometry>
        <mesh filename="package://dream_walker_description/meshes/C2_link.STL"/>
      </geometry>
      <material name="red"/>
    </visual>
    <collision>
      <origin xyz="0.3835 0.2925 0.0"/>
      <geometry>
        <mesh filename="package://dream_walker_description/meshes/C2_link.STL"/>
      </geometry>
    </collision>
    <inertial>
      <origin xyz="0.0 0.04882 -0.09719"/>
      <mass value="3.66"/>
      <inertia ixx="0.075241" ixy="0" ixz="-5e-06" iyy="0.069683" iyz="0.013776" izz="0.011896"/>
    </inertial>
  </link>
  <joint name="D2_joint" type="revolute">
    <origin rpy="0 0 0" xyz="-0.0 0.2095 0.0"/>
    <parent link="D1_link"/>
    <child link="D2_link"/>
    <axis xyz="0 1 0"/>
    <limit effort="1000" lower="-9.42" upper="9.42" velocity="1000"/>
  </joint>
  <link name="D2_link">
    <visual>
      <origin xyz="0.3835 -0.2925 0.0"/>
      <geometry>
        <mesh filename="package://dream_walker_description/meshes/D2_link.STL"/>
      </geometry>
      <material name="red"/>
    </visual>
    <collision>
      <origin xyz="0.3835 -0.2925 0.0"/>
      <geometry>
        <mesh filename="package://dream_walker_description/meshes/D2_link.STL"/>
      </geometry>
    </collision>
    <inertial>
      <origin xyz="0.0 -0.04882 -0.09719"/>
      <mass value="3.66"/>
      <inertia ixx="0.075241" ixy="0" ixz="5e-06" iyy="0.069683" iyz="-0.013776" izz="0.011896"/>
    </inertial>
  </link>
  <joint name="A3_joint" type="revolute">
    <origin rpy="0 0 0" xyz="0.0 -0.065 -0.32"/>
    <parent link="A2_link"/>
    <child link="A3_link"/>
    <axis xyz="0 1 0"/>
    <limit effort="1000" lower="-9.42" upper="9.42" velocity="1000"/>
  </joint>
  <link name="A3_link">
    <visual>
      <origin xyz="-0.3835 0.3575 0.32"/>
      <geometry>
        <mesh filename="package://dream_walker_description/meshes/A3_link.STL"/>
      </geometry>
      <material name="silver"/>
    </visual>
    <collision>
      <origin xyz="-0.3835 0.3575 0.32"/>
      <geometry>
        <mesh filename="package://dream_walker_description/meshes/A3_link.STL"/>
      </geometry>
    </collision>
    <inertial>
      <origin xyz="0.0 0.00214 -0.19011"/>
      <mass value="1.72"/>
      <inertia ixx="0.026984" ixy="0" ixz="-0" iyy="0.026649" iyz="0.000717" izz="0.001426"/>
    </inertial>
  </link>
  <joint name="B3_joint" type="revolute">
    <origin rpy="0 0 0" xyz="0.0 0.065 -0.32"/>
    <parent link="B2_link"/>
    <child link="B3_link"/>
    <axis xyz="0 1 0"/>
    <limit effort="1000" lower="-9.42" upper="9.42" velocity="1000"/>
  </joint>
  <link name="B3_link">
    <visual>
      <origin xyz="-0.3835 -0.3575 0.32"/>
      <geometry>
        <mesh filename="package://dream_walker_description/meshes/B3_link.STL"/>
      </geometry>
      <material name="silver"/>
    </visual>
    <collision>
      <origin xyz="-0.3835 -0.3575 0.32"/>
      <geometry>
        <mesh filename="package://dream_walker_description/meshes/B3_link.STL"/>
      </geometry>
    </collision>
    <inertial>
      <origin xyz="0.0 -0.00214 -0.19011"/>
      <mass value="1.72"/>
      <inertia ixx="0.026984" ixy="0" ixz="0" iyy="0.026649" iyz="-0.000717" izz="0.001426"/>
    </inertial>
  </link>
  <joint name="C3_joint" type="revolute">
    <origin rpy="0 0 0" xyz="-0.0 -0.065 -0.32"/>
    <parent link="C2_link"/>
    <child link="C3_link"/>
    <axis xyz="0 1 0"/>
    <limit effort="1000" lower="-9.42" upper="9.42" velocity="1000"/>
  </joint>
  <link name="C3_link">
    <visual>
      <origin xyz="0.3835 0.3575 0.32"/>
      <geometry>
        <mesh filename="package://dream_walker_description/meshes/C3_link.STL"/>
      </geometry>
      <material name="silver"/>
    </visual>
    <collision>
      <origin xyz="0.3835 0.3575 0.32"/>
      <geometry>
        <mesh filename="package://dream_walker_description/meshes/C3_link.STL"/>
      </geometry>
    </collision>
    <inertial>
      <origin xyz="0.0 0.00214 -0.19011"/>
      <mass value="1.72"/>
      <inertia ixx="0.026984" ixy="0" ixz="-0" iyy="0.026649" iyz="0.000717" izz="0.001426"/>
    </inertial>
  </link>
  <joint name="D3_joint" type="revolute">
    <origin rpy="0 0 0" xyz="-0.0 0.065 -0.32"/>
    <parent link="D2_link"/>
    <child link="D3_link"/>
    <axis xyz="0 1 0"/>
    <limit effort="1000" lower="-9.42" upper="9.42" velocity="1000"/>
  </joint>
  <link name="D3_link">
    <visual>
      <origin xyz="0.3835 -0.3575 0.32"/>
      <geometry>
        <mesh filename="package://dream_walker_description/meshes/D3_link.STL"/>
      </geometry>
      <material name="silver"/>
    </visual>
    <collision>
      <origin xyz="0.3835 -0.3575 0.32"/>
      <geometry>
        <mesh filename="package://dream_walker_description/meshes/D3_link.STL"/>
      </geometry>
    </collision>
    <inertial>
      <origin xyz="0.0 -0.00214 -0.19011"/>
      <mass value="1.72"/>
      <inertia ixx="0.026984" ixy="0" ixz="0" iyy="0.026649" iyz="-0.000717" izz="0.001426"/>
    </inertial>
  </link>
  <joint name="A4_joint" type="fixed">
    <origin rpy="0 0 0" xyz="0.0 -0.0 -0.443"/>
    <parent link="A3_link"/>
    <child link="A4_link"/>
  </joint>
  <link name="A4_link"/>
  <joint name="B4_joint" type="fixed">
    <origin rpy="0 0 0" xyz="0.0 0.0 -0.443"/>
    <parent link="B3_link"/>
    <child link="B4_link"/>
  </joint>
  <link name="B4_link"/>
  <joint name="C4_joint" type="fixed">
    <origin rpy="0 0 0" xyz="-0.0 -0.0 -0.443"/>
    <parent link="C3_link"/>
    <child link="C4_link"/>
  </joint>
  <link name="C4_link"/>
  <joint name="D4_joint" type="fixed">
    <origin rpy="0 0 0" xyz="-0.0 0.0 -0.443"/>
    <parent link="D3_link"/>
    <child link="D4_link"/>
  </joint>
  <link name="D4_link"/>
  <transmission name="A1_joint_trans">
    <type>transmission_interface/SimpleTransmission</type>
    <joint name="A1_joint">
      <hardwareInterface>hardware_interface/EffortJointInterface</hardwareInterface>
    </joint>
    <actuator name="A1_joint_motor">
      <hardwareInterface>hardware_interface/EffortJointInterface</hardwareInterface>
      <mechanicalReduction>1</mechanicalReduction>
    </actuator>
  </transmission>
  <transmission name="A2_joint_trans">
    <type>transmission_interface/SimpleTransmission</type>
    <joint name="A2_joint">
      <hardwareInterface>hardware_interface/EffortJointInterface</hardwareInterface>
    </joint>
    <actuator name="A2_joint_motor">
      <hardwareInterface>hardware_interface/EffortJointInterface</hardwareInterface>
      <mechanicalReduction>1</mechanicalReduction>
    </actuator>
  </transmission>
  <transmission name="A3_joint_trans">
    <type>transmission_interface/SimpleTransmission</type>
    <joint name="A3_joint">
      <hardwareInterface>hardware_interface/EffortJointInterface</hardwareInterface>
    </joint>
    <actuator name="A3_joint_motor">
      <hardwareInterface>hardware_interface/EffortJointInterface</hardwareInterface>
      <mechanicalReduction>1</mechanicalReduction>
    </actuator>
  </transmission>
  <transmission name="B1_joint_trans">
    <type>transmission_interface/SimpleTransmission</type>
    <joint name="B1_joint">
      <hardwareInterface>hardware_interface/EffortJointInterface</hardwareInterface>
    </joint>
    <actuator name="B1_joint_motor">
      <hardwareInterface>hardware_interface/EffortJointInterface</hardwareInterface>
      <mechanicalReduction>1</mechanicalReduction>
    </actuator>
  </transmission>
  <transmission name="B2_joint_trans">
    <type>transmission_interface/SimpleTransmission</type>
    <joint name="B2_joint">
      <hardwareInterface>hardware_interface/EffortJointInterface</hardwareInterface>
    </joint>
    <actuator name="B2_joint_motor">
      <hardwareInterface>hardware_interface/EffortJointInterface</hardwareInterface>
      <mechanicalReduction>1</mechanicalReduction>
    </actuator>
  </transmission>
  <transmission name="B3_joint_trans">
    <type>transmission_interface/SimpleTransmission</type>
    <joint name="B3_joint">
      <hardwareInterface>hardware_interface/EffortJointInterface</hardwareInterface>
    </joint>
    <actuator name="B3_joint_motor">
      <hardwareInterface>hardware_interface/EffortJointInterface</hardwareInterface>
      <mechanicalReduction>1</mechanicalReduction>
    </actuator>
  </transmission>
  <transmission name="C1_joint_trans">
    <type>transmission_interface/SimpleTransmission</type>
    <joint name="C1_joint">
      <hardwareInterface>hardware_interface/EffortJointInterface</hardwareInterface>
    </joint>
    <actuator name="C1_joint_motor">
      <hardwareInterface>hardware_interface/EffortJointInterface</hardwareInterface>
      <mechanicalReduction>1</mechanicalReduction>
    </actuator>
  </transmission>
  <transmission name="C2_joint_trans">
    <type>transmission_interface/SimpleTransmission</type>
    <joint name="C2_joint">
      <hardwareInterface>hardware_interface/EffortJointInterface</hardwareInterface>
    </joint>
    <actuator name="C2_joint_motor">
      <hardwareInterface>hardware_interface/EffortJointInterface</hardwareInterface>
      <mechanicalReduction>1</mechanicalReduction>
    </actuator>
  </transmission>
  <transmission name="C3_joint_trans">
    <type>transmission_interface/SimpleTransmission</type>
    <joint name="C3_joint">
      <hardwareInterface>hardware_interface/EffortJointInterface</hardwareInterface>
    </joint>
    <actuator name="C3_joint_motor">
      <hardwareInterface>hardware_interface/EffortJointInterface</hardwareInterface>
      <mechanicalReduction>1</mechanicalReduction>
    </actuator>
  </transmission>
  <transmission name="D1_joint_trans">
    <type>transmission_interface/SimpleTransmission</type>
    <joint name="D1_joint">
      <hardwareInterface>hardware_interface/EffortJointInterface</hardwareInterface>
    </joint>
    <actuator name="D1_joint_motor">
      <hardwareInterface>hardware_interface/EffortJointInterface</hardwareInterface>
      <mechanicalReduction>1</mechanicalReduction>
    </actuator>
  </transmission>
  <transmission name="D2_joint_trans">
    <type>transmission_interface/SimpleTransmission</type>
    <joint name="D2_joint">
      <hardwareInterface>hardware_interface/EffortJointInterface</hardwareInterface>
    </joint>
    <actuator name="D2_joint_motor">
      <hardwareInterface>hardware_interface/EffortJointInterface</hardwareInterface>
      <mechanicalReduction>1</mechanicalReduction>
    </actuator>
  </transmission>
  <transmission name="D3_joint_trans">
    <type>transmission_interface/SimpleTransmission</type>
    <joint name="D3_joint">
      <hardwareInterface>hardware_interface/EffortJointInterface</hardwareInterface>
    </joint>
    <actuator name="D3_joint_motor">
      <hardwareInterface>hardware_interface/EffortJointInterface</hardwareInterface>
      <mechanicalReduction>1</mechanicalReduction>
    </actuator>
  </transmission>
  <!-- =============== Gazebo =============== -->
  <!-- Body -->
  <gazebo>
    <plugin filename="libgazebo_ros_p3d.so" name="p3d_base_controller">
      <alwaysOn>true</alwaysOn>
      <updateRate>25.0</updateRate>
      <bodyName>base_link</bodyName>
      <topicName>odom/ground_truth</topicName>
      <gaussianNoise>0.01</gaussianNoise>
      <frameName>world</frameName>
      <xyzOffsets>0 0 0</xyzOffsets>
      <rpyOffsets>0 0 0</rpyOffsets>
    </plugin>
  </gazebo>
  <gazebo>
    <plugin filename="libgazebo_ros_control.so" name="gazebo_ros_control">
      <robotNamespace>/dream_walker</robotNamespace>
      <legacyModeNS>true</legacyModeNS>
    </plugin>
  </gazebo>
  <gazebo reference="body_link">
    <material>Gazebo/Gray</material>
  </gazebo>
  <gazebo reference="A0_link">
    <material>Gazebo/FratBlack</material>
    <kp>1000000.0</kp>
    <kd>1.0</kd>
    <mu1>0.8</mu1>
    <mu2>0.8</mu2>
    <maxVel>0.0</maxVel>
    <minDepth>0.001</minDepth>
  </gazebo>
  <gazebo reference="B0_link">
    <material>Gazebo/FratBlack</material>
    <kp>1000000.0</kp>
    <kd>1.0</kd>
    <mu1>0.8</mu1>
    <mu2>0.8</mu2>
    <maxVel>0.0</maxVel>
    <minDepth>0.001</minDepth>
  </gazebo>
  <gazebo reference="C0_link">
    <material>Gazebo/FratBlack</material>
    <kp>1000000.0</kp>
    <kd>1.0</kd>
    <mu1>0.8</mu1>
    <mu2>0.8</mu2>
    <maxVel>0.0</maxVel>
    <minDepth>0.001</minDepth>
  </gazebo>
  <gazebo reference="D0_link">
    <material>Gazebo/FratBlack</material>
    <kp>1000000.0</kp>
    <kd>1.0</kd>
    <mu1>0.8</mu1>
    <mu2>0.8</mu2>
    <maxVel>0.0</maxVel>
    <minDepth>0.001</minDepth>
  </gazebo>
  <gazebo reference="A1_link">
    <material>Gazebo/FratBlack</material>
    <kp>1000000.0</kp>
    <kd>1.0</kd>
    <mu1>0.8</mu1>
    <mu2>0.8</mu2>
    <maxVel>0.0</maxVel>
    <minDepth>0.001</minDepth>
  </gazebo>
  <gazebo reference="B1_link">
    <material>Gazebo/FratBlack</material>
    <kp>1000000.0</kp>
    <kd>1.0</kd>
    <mu1>0.8</mu1>
    <mu2>0.8</mu2>
    <maxVel>0.0</maxVel>
    <minDepth>0.001</minDepth>
  </gazebo>
  <gazebo reference="C1_link">
    <material>Gazebo/FratBlack</material>
    <kp>1000000.0</kp>
    <kd>1.0</kd>
    <mu1>0.8</mu1>
    <mu2>0.8</mu2>
    <maxVel>0.0</maxVel>
    <minDepth>0.001</minDepth>
  </gazebo>
  <gazebo reference="D1_link">
    <material>Gazebo/FratBlack</material>
    <kp>1000000.0</kp>
    <kd>1.0</kd>
    <mu1>0.8</mu1>
    <mu2>0.8</mu2>
    <maxVel>0.0</maxVel>
    <minDepth>0.001</minDepth>
  </gazebo>
  <gazebo reference="A2_link">
    <material>Gazebo/Red</material>
    <kp>1000000.0</kp>
    <kd>1.0</kd>
    <mu1>0.8</mu1>
    <mu2>0.8</mu2>
    <maxVel>0.0</maxVel>
    <minDepth>0.001</minDepth>
  </gazebo>
  <gazebo reference="B2_link">
    <material>Gazebo/Red</material>
    <kp>1000000.0</kp>
    <kd>1.0</kd>
    <mu1>0.8</mu1>
    <mu2>0.8</mu2>
    <maxVel>0.0</maxVel>
    <minDepth>0.001</minDepth>
  </gazebo>
  <gazebo reference="C2_link">
    <material>Gazebo/Red</material>
    <kp>1000000.0</kp>
    <kd>1.0</kd>
    <mu1>0.8</mu1>
    <mu2>0.8</mu2>
    <maxVel>0.0</maxVel>
    <minDepth>0.001</minDepth>
  </gazebo>
  <gazebo reference="D2_link">
    <material>Gazebo/Red</material>
    <kp>1000000.0</kp>
    <kd>1.0</kd>
    <mu1>0.8</mu1>
    <mu2>0.8</mu2>
    <maxVel>0.0</maxVel>
    <minDepth>0.001</minDepth>
  </gazebo>
  <gazebo reference="A3_link">
    <material>Gazebo/DarkGray</material>
    <kp>1000000.0</kp>
    <kd>1.0</kd>
    <mu1>0.8</mu1>
    <mu2>0.8</mu2>
    <maxVel>0.0</maxVel>
    <minDepth>0.001</minDepth>
  </gazebo>
  <gazebo reference="B3_link">
    <material>Gazebo/DarkGray</material>
    <kp>1000000.0</kp>
    <kd>1.0</kd>
    <mu1>0.8</mu1>
    <mu2>0.8</mu2>
    <maxVel>0.0</maxVel>
    <minDepth>0.001</minDepth>
  </gazebo>
  <gazebo reference="C3_link">
    <material>Gazebo/DarkGray</material>
    <kp>1000000.0</kp>
    <kd>1.0</kd>
    <mu1>0.8</mu1>
    <mu2>0.8</mu2>
    <maxVel>0.0</maxVel>
    <minDepth>0.001</minDepth>
  </gazebo>
  <gazebo reference="D3_link">
    <material>Gazebo/DarkGray</material>
    <kp>1000000.0</kp>
    <kd>1.0</kd>
    <mu1>0.8</mu1>
    <mu2>0.8</mu2>
    <maxVel>0.0</maxVel>
    <minDepth>0.001</minDepth>
  </gazebo>
  <gazebo reference="A4_link">
    <kp>1000000.0</kp>
    <kd>1.0</kd>
    <mu1>0.8</mu1>
    <mu2>0.8</mu2>
    <maxVel>0.0</maxVel>
    <minDepth>0.001</minDepth>
  </gazebo>
  <gazebo reference="B4_link">
    <kp>1000000.0</kp>
    <kd>1.0</kd>
    <mu1>0.8</mu1>
    <mu2>0.8</mu2>
    <maxVel>0.0</maxVel>
    <minDepth>0.001</minDepth>
  </gazebo>
  <gazebo reference="C4_link">
    <kp>1000000.0</kp>
    <kd>1.0</kd>
    <mu1>0.8</mu1>
    <mu2>0.8</mu2>
    <maxVel>0.0</maxVel>
    <minDepth>0.001</minDepth>
  </gazebo>
  <gazebo reference="D4_link">
    <kp>1000000.0</kp>
    <kd>1.0</kd>
    <mu1>0.8</mu1>
    <mu2>0.8</mu2>
    <maxVel>0.0</maxVel>
    <minDepth>0.001</minDepth>
  </gazebo>
</robot>

